{
  "comments": [
    {
      "unresolved": false,
      "key": {
        "uuid": "0dac7ac9_503c069e",
        "filename": "/PATCHSET_LEVEL",
        "patchSetId": 2
      },
      "lineNbr": 0,
      "author": {
        "id": 1
      },
      "writtenOn": "2024-04-28T01:32:32Z",
      "side": 1,
      "message": "LGTM aside from one small issue I noticed with the error logging, which I\u0027ll fix in a follow-up momentarily in the interest of expediency.\n\nNo testing required.",
      "revId": "d4ad207d2fc314e328642c8f4bdc945ba4a33ad2",
      "serverId": "cf5d0eaf-4814-484b-b55f-41cd7f22928e"
    },
    {
      "unresolved": true,
      "key": {
        "uuid": "742b8c41_586ea5fd",
        "filename": "common.py",
        "patchSetId": 2
      },
      "lineNbr": 435,
      "author": {
        "id": 1
      },
      "writtenOn": "2024-04-28T01:32:32Z",
      "side": 1,
      "message": "This won\u0027t include the type of the exception because Python, but it might be good to have that. In the interest of having this ready for games night tonight, I\u0027ll take care of this in a separate commit.",
      "revId": "d4ad207d2fc314e328642c8f4bdc945ba4a33ad2",
      "serverId": "cf5d0eaf-4814-484b-b55f-41cd7f22928e"
    }
  ],
  "submitRequirementResults": []
}